{"uuid": "88e59496-997c-4747-8b59-dee19bca682f", "children": ["843898aa-e700-4745-b729-dc9eb5f2838a", "d15a4433-cbfd-4efe-b280-84248ba66473", "96b9dcc6-fa0e-41d4-9f4e-95dae5105d3b", "529a4a6f-89a6-44e9-8f8a-97d871b0f001", "6c0cbed4-16a0-45d9-a8f0-f3eeb1f93e6e", "b0b4ef3c-8494-4313-be77-dcb0f9635ca1", "da441eb8-1217-471f-bbbb-4170f997fa14", "771cea8b-dfa4-4366-8583-66e5e1190e98", "207fff1e-13ad-4a01-af24-b57da72b410e", "345bd5d8-6fa2-4b6b-bac5-3af676aad2e1"], "befores": [{"name": "login", "status": "broken", "statusDetails": {"message": "IndexError: list index out of range\n", "trace": "  File \"C:\\Users\\Administrator\\AppData\\Local\\Packages\\PythonSoftwareFoundation.Python.3.13_qbz5n2kfra8p0\\LocalCache\\local-packages\\Python313\\site-packages\\pluggy\\_callers.py\", line 38, in run_old_style_hookwrapper\n    res = yield\n          ^^^^^\n  File \"C:\\Users\\Administrator\\AppData\\Local\\Packages\\PythonSoftwareFoundation.Python.3.13_qbz5n2kfra8p0\\LocalCache\\local-packages\\Python313\\site-packages\\pluggy\\_callers.py\", line 139, in _multicall\n    teardown.throw(exception)\n    ~~~~~~~~~~~~~~^^^^^^^^^^^\n  File \"C:\\Users\\Administrator\\AppData\\Local\\Packages\\PythonSoftwareFoundation.Python.3.13_qbz5n2kfra8p0\\LocalCache\\local-packages\\Python313\\site-packages\\_pytest\\setuponly.py\", line 36, in pytest_fixture_setup\n    return (yield)\n            ^^^^^\n  File \"C:\\Users\\Administrator\\AppData\\Local\\Packages\\PythonSoftwareFoundation.Python.3.13_qbz5n2kfra8p0\\LocalCache\\local-packages\\Python313\\site-packages\\pluggy\\_callers.py\", line 121, in _multicall\n    res = hook_impl.function(*args)\n  File \"C:\\Users\\Administrator\\AppData\\Local\\Packages\\PythonSoftwareFoundation.Python.3.13_qbz5n2kfra8p0\\LocalCache\\local-packages\\Python313\\site-packages\\_pytest\\fixtures.py\", line 1195, in pytest_fixture_setup\n    result = call_fixture_func(fixturefunc, request, kwargs)\n  File \"C:\\Users\\Administrator\\AppData\\Local\\Packages\\PythonSoftwareFoundation.Python.3.13_qbz5n2kfra8p0\\LocalCache\\local-packages\\Python313\\site-packages\\_pytest\\fixtures.py\", line 929, in call_fixture_func\n    fixture_result = fixturefunc(**kwargs)\n  File \"C:\\Users\\Administrator\\Desktop\\test\\系统设置\\系统管理设置\\网站配置管理\\test_接口缓存配置.py\", line 135, in login\n    raise e\n  File \"C:\\Users\\Administrator\\Desktop\\test\\系统设置\\系统管理设置\\网站配置管理\\test_接口缓存配置.py\", line 108, in login\n    captcha_data = captcha_img.get_attribute(\"src\").split(\",\")[1]\n                   ~~~~~~~~~~~~~~~~~~~~~~~~~~~~~~~~~~~~~~~~~~~^^^\n"}, "attachments": [{"name": "登录失败截图", "source": "39e8bf93-a8ea-4686-9491-eaacf4edff98-attachment.png", "type": "image/png"}], "start": 1753498153056, "stop": 1753498155383}], "start": 1753498153056, "stop": 1753498156216}